<?xml version='1.0' encoding='ASCII'?>
<robot name="Scene">
  <link name="drawer_0.333_0.958_0.998_0_corpus">
    <inertial>
      <origin xyz="0.0 0.0 0.0" rpy="0.0 -0.0 0.0" />
      <mass value="0.054318599999999995" />
      <inertia ixx="1.0" ixy="0.0" ixz="0.0" iyy="1.0" iyz="0.0" izz="1.0" />
    </inertial>
    <visual name="drawer_0.333_0.958_0.998_0_back">
      <geometry>
        <box size="0.958 0.02 0.313" />
      </geometry>
      <origin xyz="0.0 0.489 0.1565" rpy="0.0 -0.0 0.0" />
      <material name="drawer_0.333_0.958_0.998_0_back_main_color">
        <color rgba="0.4 0.4 0.4 1.0" />
      </material>
    </visual>
    <visual name="drawer_0.333_0.958_0.998_0_left">
      <geometry>
        <box size="0.02 0.958 0.313" />
      </geometry>
      <origin xyz="-0.469 0.0 0.1565" rpy="0.0 -0.0 0.0" />
      <material name="drawer_0.333_0.958_0.998_0_left_main_color">
        <color rgba="0.4 0.4 0.4 1.0" />
      </material>
    </visual>
    <visual name="drawer_0.333_0.958_0.998_0_right">
      <geometry>
        <box size="0.02 0.958 0.313" />
      </geometry>
      <origin xyz="0.469 0.0 0.1565" rpy="0.0 -0.0 0.0" />
      <material name="drawer_0.333_0.958_0.998_0_right_main_color">
        <color rgba="0.4 0.4 0.4 1.0" />
      </material>
    </visual>
    <visual name="drawer_0.333_0.958_0.998_0_surface_0_0">
      <geometry>
        <box size="0.9179999999999999 0.958 0.02" />
      </geometry>
      <origin xyz="0.0 0.0 0.009999999999999962" rpy="0.0 -0.0 0.0" />
      <material name="drawer_0.333_0.958_0.998_0_surface_0_0_main_color">
        <color rgba="0.4 0.4 0.4 1.0" />
      </material>
    </visual>
    <visual name="drawer_0.333_0.958_0.998_0_top">
      <geometry>
        <box size="0.958 0.978 0.02" />
      </geometry>
      <origin xyz="0.0 0.01 0.323" rpy="0.0 -0.0 0.0" />
      <material name="drawer_0.333_0.958_0.998_0_top_main_color">
        <color rgba="0.4 0.4 0.4 1.0" />
      </material>
    </visual>
    <collision name="drawer_0.333_0.958_0.998_0_back">
      <geometry>
        <box size="0.958 0.02 0.313" />
      </geometry>
      <origin xyz="0.0 0.489 0.1565" rpy="0.0 -0.0 0.0" />
    </collision>
    <collision name="drawer_0.333_0.958_0.998_0_left">
      <geometry>
        <box size="0.02 0.958 0.313" />
      </geometry>
      <origin xyz="-0.469 0.0 0.1565" rpy="0.0 -0.0 0.0" />
    </collision>
    <collision name="drawer_0.333_0.958_0.998_0_right">
      <geometry>
        <box size="0.02 0.958 0.313" />
      </geometry>
      <origin xyz="0.469 0.0 0.1565" rpy="0.0 -0.0 0.0" />
    </collision>
    <collision name="drawer_0.333_0.958_0.998_0_surface_0_0">
      <geometry>
        <box size="0.9179999999999999 0.958 0.02" />
      </geometry>
      <origin xyz="0.0 0.0 0.009999999999999962" rpy="0.0 -0.0 0.0" />
    </collision>
    <collision name="drawer_0.333_0.958_0.998_0_top">
      <geometry>
        <box size="0.958 0.978 0.02" />
      </geometry>
      <origin xyz="0.0 0.01 0.323" rpy="0.0 -0.0 0.0" />
    </collision>
  </link>
  <link name="drawer_0.333_0.958_0.998_0_drawer_0_0">
    <inertial>
      <origin xyz="0.0 0.0 0.0" rpy="0.0 -0.0 0.0" />
      <mass value="0.1" />
      <inertia ixx="1.0" ixy="0.0" ixz="0.0" iyy="1.0" iyz="0.0" izz="1.0" />
    </inertial>
    <visual><geometry><mesh filename="full_pipeline_simple/drawer_0.333_0.958_0.998_0.obj" /></geometry><material name="drawer_0.333_0.958_0.998_0_drawer_0_0_material"><color rgba="0.8 0.8 0.8 1.0" /></material></visual><collision><geometry><box size="0.954000 0.990300 0.329000" /></geometry><origin xyz="0.000000 0.365050 0.000000" rpy="0 0 0" /></collision></link>
  <link name="drawer_0.333_0.958_0.998_1_corpus">
    <inertial>
      <origin xyz="0.0 0.0 0.0" rpy="0.0 -0.0 0.0" />
      <mass value="0.054318599999999995" />
      <inertia ixx="1.0" ixy="0.0" ixz="0.0" iyy="1.0" iyz="0.0" izz="1.0" />
    </inertial>
    <visual name="drawer_0.333_0.958_0.998_1_back">
      <geometry>
        <box size="0.958 0.02 0.313" />
      </geometry>
      <origin xyz="0.0 0.489 0.1565" rpy="0.0 -0.0 0.0" />
      <material name="drawer_0.333_0.958_0.998_1_back_main_color">
        <color rgba="0.4 0.4 0.4 1.0" />
      </material>
    </visual>
    <visual name="drawer_0.333_0.958_0.998_1_left">
      <geometry>
        <box size="0.02 0.958 0.313" />
      </geometry>
      <origin xyz="-0.469 0.0 0.1565" rpy="0.0 -0.0 0.0" />
      <material name="drawer_0.333_0.958_0.998_1_left_main_color">
        <color rgba="0.4 0.4 0.4 1.0" />
      </material>
    </visual>
    <visual name="drawer_0.333_0.958_0.998_1_right">
      <geometry>
        <box size="0.02 0.958 0.313" />
      </geometry>
      <origin xyz="0.469 0.0 0.1565" rpy="0.0 -0.0 0.0" />
      <material name="drawer_0.333_0.958_0.998_1_right_main_color">
        <color rgba="0.4 0.4 0.4 1.0" />
      </material>
    </visual>
    <visual name="drawer_0.333_0.958_0.998_1_surface_0_0">
      <geometry>
        <box size="0.9179999999999999 0.958 0.02" />
      </geometry>
      <origin xyz="0.0 0.0 0.009999999999999962" rpy="0.0 -0.0 0.0" />
      <material name="drawer_0.333_0.958_0.998_1_surface_0_0_main_color">
        <color rgba="0.4 0.4 0.4 1.0" />
      </material>
    </visual>
    <visual name="drawer_0.333_0.958_0.998_1_top">
      <geometry>
        <box size="0.958 0.978 0.02" />
      </geometry>
      <origin xyz="0.0 0.01 0.323" rpy="0.0 -0.0 0.0" />
      <material name="drawer_0.333_0.958_0.998_1_top_main_color">
        <color rgba="0.4 0.4 0.4 1.0" />
      </material>
    </visual>
    <collision name="drawer_0.333_0.958_0.998_1_back">
      <geometry>
        <box size="0.958 0.02 0.313" />
      </geometry>
      <origin xyz="0.0 0.489 0.1565" rpy="0.0 -0.0 0.0" />
    </collision>
    <collision name="drawer_0.333_0.958_0.998_1_left">
      <geometry>
        <box size="0.02 0.958 0.313" />
      </geometry>
      <origin xyz="-0.469 0.0 0.1565" rpy="0.0 -0.0 0.0" />
    </collision>
    <collision name="drawer_0.333_0.958_0.998_1_right">
      <geometry>
        <box size="0.02 0.958 0.313" />
      </geometry>
      <origin xyz="0.469 0.0 0.1565" rpy="0.0 -0.0 0.0" />
    </collision>
    <collision name="drawer_0.333_0.958_0.998_1_surface_0_0">
      <geometry>
        <box size="0.9179999999999999 0.958 0.02" />
      </geometry>
      <origin xyz="0.0 0.0 0.009999999999999962" rpy="0.0 -0.0 0.0" />
    </collision>
    <collision name="drawer_0.333_0.958_0.998_1_top">
      <geometry>
        <box size="0.958 0.978 0.02" />
      </geometry>
      <origin xyz="0.0 0.01 0.323" rpy="0.0 -0.0 0.0" />
    </collision>
  </link>
  <link name="drawer_0.333_0.958_0.998_1_drawer_0_0">
    <inertial>
      <origin xyz="0.0 0.0 0.0" rpy="0.0 -0.0 0.0" />
      <mass value="0.1" />
      <inertia ixx="1.0" ixy="0.0" ixz="0.0" iyy="1.0" iyz="0.0" izz="1.0" />
    </inertial>
    <visual><geometry><mesh filename="full_pipeline_simple/drawer_0.333_0.958_0.998_1.obj" /></geometry><material name="drawer_0.333_0.958_0.998_1_drawer_0_0_material"><color rgba="0.8 0.8 0.8 1.0" /></material></visual><collision><geometry><box size="0.954000 0.990300 0.329000" /></geometry><origin xyz="0.000000 0.365050 0.000000" rpy="0 0 0" /></collision></link>
  <link name="lower_left_cabinet_1.003_0.958_0.998_0_corpus">
    <inertial>
      <origin xyz="0.0 0.0 0.0" rpy="0.0 -0.0 0.0" />
      <mass value="0.10162463999999999" />
      <inertia ixx="1.0" ixy="0.0" ixz="0.0" iyy="1.0" iyz="0.0" izz="1.0" />
    </inertial>
    <visual name="lower_left_cabinet_1.003_0.958_0.998_0_back">
      <geometry>
        <box size="0.958 0.02 0.9829999999999999" />
      </geometry>
      <origin xyz="0.0 0.489 0.49149999999999994" rpy="0.0 -0.0 0.0" />
      <material name="lower_left_cabinet_1.003_0.958_0.998_0_back_main_color">
        <color rgba="0.4 0.4 0.4 1.0" />
      </material>
    </visual>
    <visual name="lower_left_cabinet_1.003_0.958_0.998_0_left">
      <geometry>
        <box size="0.02 0.958 0.9829999999999999" />
      </geometry>
      <origin xyz="-0.469 0.0 0.49149999999999994" rpy="0.0 -0.0 0.0" />
      <material name="lower_left_cabinet_1.003_0.958_0.998_0_left_main_color">
        <color rgba="0.4 0.4 0.4 1.0" />
      </material>
    </visual>
    <visual name="lower_left_cabinet_1.003_0.958_0.998_0_right">
      <geometry>
        <box size="0.02 0.958 0.9829999999999999" />
      </geometry>
      <origin xyz="0.469 0.0 0.49149999999999994" rpy="0.0 -0.0 0.0" />
      <material name="lower_left_cabinet_1.003_0.958_0.998_0_right_main_color">
        <color rgba="0.4 0.4 0.4 1.0" />
      </material>
    </visual>
    <visual name="lower_left_cabinet_1.003_0.958_0.998_0_shelf_0_0_0">
      <geometry>
        <box size="0.9179999999999999 0.958 0.01" />
      </geometry>
      <origin xyz="0.0 0.0 0.5015" rpy="0.0 -0.0 0.0" />
      <material name="lower_left_cabinet_1.003_0.958_0.998_0_shelf_0_0_0_main_color">
        <color rgba="0.4 0.4 0.4 1.0" />
      </material>
    </visual>
    <visual name="lower_left_cabinet_1.003_0.958_0.998_0_surface_0_0">
      <geometry>
        <box size="0.9179999999999999 0.958 0.02" />
      </geometry>
      <origin xyz="0.0 0.0 0.010000000000000018" rpy="0.0 -0.0 0.0" />
      <material name="lower_left_cabinet_1.003_0.958_0.998_0_surface_0_0_main_color">
        <color rgba="0.4 0.4 0.4 1.0" />
      </material>
    </visual>
    <visual name="lower_left_cabinet_1.003_0.958_0.998_0_top">
      <geometry>
        <box size="0.958 0.978 0.02" />
      </geometry>
      <origin xyz="0.0 0.01 0.9929999999999999" rpy="0.0 -0.0 0.0" />
      <material name="lower_left_cabinet_1.003_0.958_0.998_0_top_main_color">
        <color rgba="0.4 0.4 0.4 1.0" />
      </material>
    </visual>
    <collision name="lower_left_cabinet_1.003_0.958_0.998_0_back">
      <geometry>
        <box size="0.958 0.02 0.9829999999999999" />
      </geometry>
      <origin xyz="0.0 0.489 0.49149999999999994" rpy="0.0 -0.0 0.0" />
    </collision>
    <collision name="lower_left_cabinet_1.003_0.958_0.998_0_left">
      <geometry>
        <box size="0.02 0.958 0.9829999999999999" />
      </geometry>
      <origin xyz="-0.469 0.0 0.49149999999999994" rpy="0.0 -0.0 0.0" />
    </collision>
    <collision name="lower_left_cabinet_1.003_0.958_0.998_0_right">
      <geometry>
        <box size="0.02 0.958 0.9829999999999999" />
      </geometry>
      <origin xyz="0.469 0.0 0.49149999999999994" rpy="0.0 -0.0 0.0" />
    </collision>
    <collision name="lower_left_cabinet_1.003_0.958_0.998_0_shelf_0_0_0">
      <geometry>
        <box size="0.9179999999999999 0.958 0.01" />
      </geometry>
      <origin xyz="0.0 0.0 0.5015" rpy="0.0 -0.0 0.0" />
    </collision>
    <collision name="lower_left_cabinet_1.003_0.958_0.998_0_surface_0_0">
      <geometry>
        <box size="0.9179999999999999 0.958 0.02" />
      </geometry>
      <origin xyz="0.0 0.0 0.010000000000000018" rpy="0.0 -0.0 0.0" />
    </collision>
    <collision name="lower_left_cabinet_1.003_0.958_0.998_0_top">
      <geometry>
        <box size="0.958 0.978 0.02" />
      </geometry>
      <origin xyz="0.0 0.01 0.9929999999999999" rpy="0.0 -0.0 0.0" />
    </collision>
  </link>
  <link name="lower_left_cabinet_1.003_0.958_0.998_0_door_0_0">
    <inertial>
      <origin xyz="0.0 0.0 0.0" rpy="0.0 -0.0 0.0" />
      <mass value="0.1" />
      <inertia ixx="1.0" ixy="0.0" ixz="0.0" iyy="1.0" iyz="0.0" izz="1.0" />
    </inertial>
    <visual><geometry><mesh filename="full_pipeline_simple/lower_left_cabinet_1.003_0.958_0.998_0.obj" /></geometry><material name="lower_left_cabinet_1.003_0.958_0.998_0_door_0_0_material"><color rgba="0.8 0.8 0.8 1.0" /></material></visual><collision><geometry><box size="0.954000 0.168200 0.999000" /></geometry><origin xyz="-0.477000 -0.026000 0.000000" rpy="0 0 0" /></collision></link>
  <link name="lower_right_cabinet_1.003_0.958_0.998_0_corpus">
    <inertial>
      <origin xyz="0.0 0.0 0.0" rpy="0.0 -0.0 0.0" />
      <mass value="0.10162463999999999" />
      <inertia ixx="1.0" ixy="0.0" ixz="0.0" iyy="1.0" iyz="0.0" izz="1.0" />
    </inertial>
    <visual name="lower_right_cabinet_1.003_0.958_0.998_0_back">
      <geometry>
        <box size="0.958 0.02 0.9829999999999999" />
      </geometry>
      <origin xyz="0.0 0.489 0.49149999999999994" rpy="0.0 -0.0 0.0" />
      <material name="lower_right_cabinet_1.003_0.958_0.998_0_back_main_color">
        <color rgba="0.4 0.4 0.4 1.0" />
      </material>
    </visual>
    <visual name="lower_right_cabinet_1.003_0.958_0.998_0_left">
      <geometry>
        <box size="0.02 0.958 0.9829999999999999" />
      </geometry>
      <origin xyz="-0.469 0.0 0.49149999999999994" rpy="0.0 -0.0 0.0" />
      <material name="lower_right_cabinet_1.003_0.958_0.998_0_left_main_color">
        <color rgba="0.4 0.4 0.4 1.0" />
      </material>
    </visual>
    <visual name="lower_right_cabinet_1.003_0.958_0.998_0_right">
      <geometry>
        <box size="0.02 0.958 0.9829999999999999" />
      </geometry>
      <origin xyz="0.469 0.0 0.49149999999999994" rpy="0.0 -0.0 0.0" />
      <material name="lower_right_cabinet_1.003_0.958_0.998_0_right_main_color">
        <color rgba="0.4 0.4 0.4 1.0" />
      </material>
    </visual>
    <visual name="lower_right_cabinet_1.003_0.958_0.998_0_shelf_0_0_0">
      <geometry>
        <box size="0.9179999999999999 0.958 0.01" />
      </geometry>
      <origin xyz="0.0 0.0 0.5015" rpy="0.0 -0.0 0.0" />
      <material name="lower_right_cabinet_1.003_0.958_0.998_0_shelf_0_0_0_main_color">
        <color rgba="0.4 0.4 0.4 1.0" />
      </material>
    </visual>
    <visual name="lower_right_cabinet_1.003_0.958_0.998_0_surface_0_0">
      <geometry>
        <box size="0.9179999999999999 0.958 0.02" />
      </geometry>
      <origin xyz="0.0 0.0 0.010000000000000018" rpy="0.0 -0.0 0.0" />
      <material name="lower_right_cabinet_1.003_0.958_0.998_0_surface_0_0_main_color">
        <color rgba="0.4 0.4 0.4 1.0" />
      </material>
    </visual>
    <visual name="lower_right_cabinet_1.003_0.958_0.998_0_top">
      <geometry>
        <box size="0.958 0.978 0.02" />
      </geometry>
      <origin xyz="0.0 0.01 0.9929999999999999" rpy="0.0 -0.0 0.0" />
      <material name="lower_right_cabinet_1.003_0.958_0.998_0_top_main_color">
        <color rgba="0.4 0.4 0.4 1.0" />
      </material>
    </visual>
    <collision name="lower_right_cabinet_1.003_0.958_0.998_0_back">
      <geometry>
        <box size="0.958 0.02 0.9829999999999999" />
      </geometry>
      <origin xyz="0.0 0.489 0.49149999999999994" rpy="0.0 -0.0 0.0" />
    </collision>
    <collision name="lower_right_cabinet_1.003_0.958_0.998_0_left">
      <geometry>
        <box size="0.02 0.958 0.9829999999999999" />
      </geometry>
      <origin xyz="-0.469 0.0 0.49149999999999994" rpy="0.0 -0.0 0.0" />
    </collision>
    <collision name="lower_right_cabinet_1.003_0.958_0.998_0_right">
      <geometry>
        <box size="0.02 0.958 0.9829999999999999" />
      </geometry>
      <origin xyz="0.469 0.0 0.49149999999999994" rpy="0.0 -0.0 0.0" />
    </collision>
    <collision name="lower_right_cabinet_1.003_0.958_0.998_0_shelf_0_0_0">
      <geometry>
        <box size="0.9179999999999999 0.958 0.01" />
      </geometry>
      <origin xyz="0.0 0.0 0.5015" rpy="0.0 -0.0 0.0" />
    </collision>
    <collision name="lower_right_cabinet_1.003_0.958_0.998_0_surface_0_0">
      <geometry>
        <box size="0.9179999999999999 0.958 0.02" />
      </geometry>
      <origin xyz="0.0 0.0 0.010000000000000018" rpy="0.0 -0.0 0.0" />
    </collision>
    <collision name="lower_right_cabinet_1.003_0.958_0.998_0_top">
      <geometry>
        <box size="0.958 0.978 0.02" />
      </geometry>
      <origin xyz="0.0 0.01 0.9929999999999999" rpy="0.0 -0.0 0.0" />
    </collision>
  </link>
  <link name="lower_right_cabinet_1.003_0.958_0.998_0_door_0_0">
    <inertial>
      <origin xyz="0.0 0.0 0.0" rpy="0.0 -0.0 0.0" />
      <mass value="0.1" />
      <inertia ixx="1.0" ixy="0.0" ixz="0.0" iyy="1.0" iyz="0.0" izz="1.0" />
    </inertial>
    <visual><geometry><mesh filename="full_pipeline_simple/lower_right_cabinet_1.003_0.958_0.998_0.obj" /></geometry><material name="lower_right_cabinet_1.003_0.958_0.998_0_door_0_0_material"><color rgba="0.8 0.8 0.8 1.0" /></material></visual><collision><geometry><box size="0.954000 0.168200 0.999000" /></geometry><origin xyz="0.477000 -0.026000 0.000000" rpy="0 0 0" /></collision></link>
  <link name="world" />
  <link name="drawer_0.333_0.958_0.998_0" />
  <link name="drawer_0.333_0.958_0.998_1" />
  <link name="lower_left_cabinet_1.003_0.958_0.998_0" />
  <link name="lower_right_cabinet_1.003_0.958_0.998_0" />
  <joint name="drawer_0.333_0.958_0.998_0_world_fixed_joint" type="fixed">
    <parent link="world" />
    <child link="drawer_0.333_0.958_0.998_0" />
    <origin xyz="0.0 0.0 0.0" rpy="0.0 -0.0 0.0" />
  </joint>
  <joint name="drawer_0.333_0.958_0.998_0_corpus_to_drawer_0_0" type="prismatic">
    <parent link="drawer_0.333_0.958_0.998_0_corpus" />
    <child link="drawer_0.333_0.958_0.998_0_drawer_0_0" />
    <origin xyz="0.0 -0.479 0.16649999999999998" rpy="0.0 -0.0 0.0" />
    <axis xyz="0 -1 0" />
    <limit effort="1000.0" velocity="1.0" lower="0.0" upper="0.79218" />
  </joint>
  <joint name="drawer_0.333_0.958_0.998_0_origin_joint" type="fixed">
    <parent link="drawer_0.333_0.958_0.998_0" />
    <child link="drawer_0.333_0.958_0.998_0_corpus" />
    <origin xyz="0.0 0.0 0.0" rpy="0.0 -0.0 0.0" />
  </joint>
  <joint name="drawer_0.333_0.958_0.998_1_world_fixed_joint" type="fixed">
    <parent link="world" />
    <child link="drawer_0.333_0.958_0.998_1" />
    <origin xyz="0.958 0.0 0.0" rpy="0.0 -0.0 0.0" />
  </joint>
  <joint name="drawer_0.333_0.958_0.998_1_corpus_to_drawer_0_0" type="prismatic">
    <parent link="drawer_0.333_0.958_0.998_1_corpus" />
    <child link="drawer_0.333_0.958_0.998_1_drawer_0_0" />
    <origin xyz="0.0 -0.479 0.16649999999999998" rpy="0.0 -0.0 0.0" />
    <axis xyz="0 -1 0" />
    <limit effort="1000.0" velocity="1.0" lower="0.0" upper="0.79218" />
  </joint>
  <joint name="drawer_0.333_0.958_0.998_1_origin_joint" type="fixed">
    <parent link="drawer_0.333_0.958_0.998_1" />
    <child link="drawer_0.333_0.958_0.998_1_corpus" />
    <origin xyz="0.0 0.0 0.0" rpy="0.0 -0.0 0.0" />
  </joint>
  <joint name="lower_left_cabinet_1.003_0.958_0.998_0_world_fixed_joint" type="fixed">
    <parent link="world" />
    <child link="lower_left_cabinet_1.003_0.958_0.998_0" />
    <origin xyz="0.958 0.0 -1.003" rpy="0.0 -0.0 0.0" />
  </joint>
  <joint name="lower_left_cabinet_1.003_0.958_0.998_0_corpus_to_door_0_0" type="revolute">
    <parent link="lower_left_cabinet_1.003_0.958_0.998_0_corpus" />
    <child link="lower_left_cabinet_1.003_0.958_0.998_0_door_0_0" />
    <origin xyz="0.477 -0.499 0.5015" rpy="0.0 -0.0 0.0" />
    <axis xyz="0 0 1" />
    <limit effort="1000.0" velocity="0.1" lower="0.0" upper="1.5707963267948966" />
  </joint>
  <joint name="lower_left_cabinet_1.003_0.958_0.998_0_origin_joint" type="fixed">
    <parent link="lower_left_cabinet_1.003_0.958_0.998_0" />
    <child link="lower_left_cabinet_1.003_0.958_0.998_0_corpus" />
    <origin xyz="0.0 0.0 0.0" rpy="0.0 -0.0 0.0" />
  </joint>
  <joint name="lower_right_cabinet_1.003_0.958_0.998_0_world_fixed_joint" type="fixed">
    <parent link="world" />
    <child link="lower_right_cabinet_1.003_0.958_0.998_0" />
    <origin xyz="0.0 0.0 -1.003" rpy="0.0 -0.0 0.0" />
  </joint>
  <joint name="lower_right_cabinet_1.003_0.958_0.998_0_corpus_to_door_0_0" type="revolute">
    <parent link="lower_right_cabinet_1.003_0.958_0.998_0_corpus" />
    <child link="lower_right_cabinet_1.003_0.958_0.998_0_door_0_0" />
    <origin xyz="-0.477 -0.499 0.5015" rpy="0.0 -0.0 0.0" />
    <axis xyz="0 0 -1" />
    <limit effort="1000.0" velocity="0.1" lower="0.0" upper="1.5707963267948966" />
  </joint>
  <joint name="lower_right_cabinet_1.003_0.958_0.998_0_origin_joint" type="fixed">
    <parent link="lower_right_cabinet_1.003_0.958_0.998_0" />
    <child link="lower_right_cabinet_1.003_0.958_0.998_0_corpus" />
    <origin xyz="0.0 0.0 0.0" rpy="0.0 -0.0 0.0" />
  </joint>
</robot>