<?xml version='1.0' encoding='ASCII'?>
<robot name="Scene">
  <link name="cabinet_corpus">
    <inertial>
      <origin xyz="0.0 0.0 0.0" rpy="0.0 -0.0 0.0"/>
      <mass value="0.026479649999999993"/>
      <inertia ixx="1.0" ixy="0.0" ixz="0.0" iyy="1.0" iyz="0.0" izz="1.0"/>
    </inertial>
    <visual name="cabinet_back">
      <geometry>
        <box size="0.361 0.02 0.58"/>
      </geometry>
      <origin xyz="0.0 0.2865 0.29" rpy="0.0 -0.0 0.0"/>
      <material name="cabinet_back_main_color">
        <color rgba="0.4 0.4 0.4 1.0"/>
      </material>
    </visual>
    <visual name="cabinet_left">
      <geometry>
        <box size="0.02 0.5529999999999999 0.58"/>
      </geometry>
      <origin xyz="-0.17049999999999998 0.0 0.29" rpy="0.0 -0.0 0.0"/>
      <material name="cabinet_left_main_color">
        <color rgba="0.4 0.4 0.4 1.0"/>
      </material>
    </visual>
    <visual name="cabinet_right">
      <geometry>
        <box size="0.02 0.5529999999999999 0.58"/>
      </geometry>
      <origin xyz="0.17049999999999998 0.0 0.29" rpy="0.0 -0.0 0.0"/>
      <material name="cabinet_right_main_color">
        <color rgba="0.4 0.4 0.4 1.0"/>
      </material>
    </visual>
    <visual name="cabinet_shelf_0_0_0">
      <geometry>
        <box size="0.321 0.5529999999999999 0.01"/>
      </geometry>
      <origin xyz="0.0 0.0 0.3" rpy="0.0 -0.0 0.0"/>
      <material name="cabinet_shelf_0_0_0_main_color">
        <color rgba="0.4 0.4 0.4 1.0"/>
      </material>
    </visual>
    <visual name="cabinet_surface_0_0">
      <geometry>
        <box size="0.321 0.5529999999999999 0.02"/>
      </geometry>
      <origin xyz="0.0 0.0 0.010000000000000018" rpy="0.0 -0.0 0.0"/>
      <material name="cabinet_surface_0_0_main_color">
        <color rgba="0.4 0.4 0.4 1.0"/>
      </material>
    </visual>
    <visual name="cabinet_top">
      <geometry>
        <box size="0.361 0.573 0.02"/>
      </geometry>
      <origin xyz="0.0 0.01 0.59" rpy="0.0 -0.0 0.0"/>
      <material name="cabinet_top_main_color">
        <color rgba="0.4 0.4 0.4 1.0"/>
      </material>
    </visual>
    <collision name="cabinet_back">
      <geometry>
        <box size="0.361 0.02 0.58"/>
      </geometry>
      <origin xyz="0.0 0.2865 0.29" rpy="0.0 -0.0 0.0"/>
    </collision>
    <collision name="cabinet_left">
      <geometry>
        <box size="0.02 0.5529999999999999 0.58"/>
      </geometry>
      <origin xyz="-0.17049999999999998 0.0 0.29" rpy="0.0 -0.0 0.0"/>
    </collision>
    <collision name="cabinet_right">
      <geometry>
        <box size="0.02 0.5529999999999999 0.58"/>
      </geometry>
      <origin xyz="0.17049999999999998 0.0 0.29" rpy="0.0 -0.0 0.0"/>
    </collision>
    <collision name="cabinet_shelf_0_0_0">
      <geometry>
        <box size="0.321 0.5529999999999999 0.01"/>
      </geometry>
      <origin xyz="0.0 0.0 0.3" rpy="0.0 -0.0 0.0"/>
    </collision>
    <collision name="cabinet_surface_0_0">
      <geometry>
        <box size="0.321 0.5529999999999999 0.02"/>
      </geometry>
      <origin xyz="0.0 0.0 0.010000000000000018" rpy="0.0 -0.0 0.0"/>
    </collision>
    <collision name="cabinet_top">
      <geometry>
        <box size="0.361 0.573 0.02"/>
      </geometry>
      <origin xyz="0.0 0.01 0.59" rpy="0.0 -0.0 0.0"/>
    </collision>
  </link>
  <link name="cabinet_door_0_0">
    <inertial>
      <origin xyz="0.0 0.0 0.0" rpy="0.0 -0.0 0.0"/>
      <mass value="0.10000000000000003"/>
      <inertia ixx="1.0" ixy="0.0" ixz="0.0" iyy="1.0" iyz="0.0" izz="1.0"/>
    </inertial>
    <visual name="cabinet_door_0_0_door">
      <geometry>
        <box size="0.357 0.02 0.596"/>
      </geometry>
      <origin xyz="-0.1785 0.01 0.0" rpy="0.0 -0.0 0.0"/>
      <material name="cabinet_door_0_0_door_main_color">
        <color rgba="0.4 0.4 0.4 1.0"/>
      </material>
    </visual>
    <visual name="cabinet_door_0_0_handle_part_0">
      <geometry>
        <box size="0.024 0.1682 0.024"/>
      </geometry>
      <origin xyz="-0.295 -0.026 0.0" rpy="1.5707963267948966 -0.0 1.5707963267948966"/>
      <material name="cabinet_door_0_0_handle_part_0_main_color">
        <color rgba="0.4 0.4 0.4 1.0"/>
      </material>
    </visual>
    <visual name="cabinet_door_0_0_handle_part_1">
      <geometry>
        <box size="0.013999999999999999 0.04 0.024"/>
      </geometry>
      <origin xyz="-0.295 -0.006999999999999999 -0.06409999999999999" rpy="1.5707963267948966 -0.0 1.5707963267948966"/>
      <material name="cabinet_door_0_0_handle_part_1_main_color">
        <color rgba="0.4 0.4 0.4 1.0"/>
      </material>
    </visual>
    <visual name="cabinet_door_0_0_handle_part_2">
      <geometry>
        <box size="0.013999999999999999 0.04 0.024"/>
      </geometry>
      <origin xyz="-0.295 -0.006999999999999999 0.06409999999999999" rpy="1.5707963267948966 -0.0 1.5707963267948966"/>
      <material name="cabinet_door_0_0_handle_part_2_main_color">
        <color rgba="0.4 0.4 0.4 1.0"/>
      </material>
    </visual>
    <collision name="cabinet_door_0_0_door">
      <geometry>
        <box size="0.357 0.02 0.596"/>
      </geometry>
      <origin xyz="-0.1785 0.01 0.0" rpy="0.0 -0.0 0.0"/>
    </collision>
    <collision name="cabinet_door_0_0_handle_part_0">
      <geometry>
        <box size="0.024 0.1682 0.024"/>
      </geometry>
      <origin xyz="-0.295 -0.026 0.0" rpy="1.5707963267948966 -0.0 1.5707963267948966"/>
    </collision>
    <collision name="cabinet_door_0_0_handle_part_1">
      <geometry>
        <box size="0.013999999999999999 0.04 0.024"/>
      </geometry>
      <origin xyz="-0.295 -0.006999999999999999 -0.06409999999999999" rpy="1.5707963267948966 -0.0 1.5707963267948966"/>
    </collision>
    <collision name="cabinet_door_0_0_handle_part_2">
      <geometry>
        <box size="0.013999999999999999 0.04 0.024"/>
      </geometry>
      <origin xyz="-0.295 -0.006999999999999999 0.06409999999999999" rpy="1.5707963267948966 -0.0 1.5707963267948966"/>
    </collision>
  </link>
  <link name="world"/>
  <link name="cabinet"/>
  <joint name="cabinet_world_fixed_joint" type="fixed">
    <parent link="world"/>
    <child link="cabinet"/>
    <origin xyz="0.0 0.0 0.0" rpy="0.0 -0.0 0.0"/>
  </joint>
  <joint name="cabinet_corpus_to_door_0_0" type="revolute">
    <parent link="cabinet_corpus"/>
    <child link="cabinet_door_0_0"/>
    <origin xyz="0.1785 -0.2965 0.3" rpy="0.0 -0.0 0.0"/>
    <axis xyz="0 0 1"/>
    <limit effort="1000.0" velocity="0.1" lower="0.0" upper="1.5707963267948966"/>
  </joint>
  <joint name="cabinet_origin_joint" type="fixed">
    <parent link="cabinet"/>
    <child link="cabinet_corpus"/>
    <origin xyz="0.0 0.0 0.0" rpy="0.0 -0.0 0.0"/>
  </joint>
</robot>
