<?xml version='1.0' encoding='ASCII'?>
<robot name="Scene">
  <link name="drawer_corpus">
    <inertial>
      <origin xyz="0.0 0.0 0.0" rpy="0.0 -0.0 0.0" />
      <mass value="0.012323039999999999" />
      <inertia ixx="1.0" ixy="0.0" ixz="0.0" iyy="1.0" iyz="0.0" izz="1.0" />
    </inertial>
    <visual name="drawer_back">
      <geometry>
        <box size="0.361 0.02 0.158" />
      </geometry>
      <origin xyz="0.0 0.2865 0.079" rpy="0.0 -0.0 0.0" />
      <material name="drawer_back_main_color">
        <color rgba="0.4 0.4 0.4 1.0" />
      </material>
    </visual>
    <visual name="drawer_left">
      <geometry>
        <box size="0.02 0.5529999999999999 0.158" />
      </geometry>
      <origin xyz="-0.17049999999999998 0.0 0.079" rpy="0.0 -0.0 0.0" />
      <material name="drawer_left_main_color">
        <color rgba="0.4 0.4 0.4 1.0" />
      </material>
    </visual>
    <visual name="drawer_right">
      <geometry>
        <box size="0.02 0.5529999999999999 0.158" />
      </geometry>
      <origin xyz="0.17049999999999998 0.0 0.079" rpy="0.0 -0.0 0.0" />
      <material name="drawer_right_main_color">
        <color rgba="0.4 0.4 0.4 1.0" />
      </material>
    </visual>
    <visual name="drawer_surface_0_0">
      <geometry>
        <box size="0.321 0.5529999999999999 0.02" />
      </geometry>
      <origin xyz="0.0 0.0 0.010000000000000018" rpy="0.0 -0.0 0.0" />
      <material name="drawer_surface_0_0_main_color">
        <color rgba="0.4 0.4 0.4 1.0" />
      </material>
    </visual>
    <visual name="drawer_top">
      <geometry>
        <box size="0.361 0.573 0.02" />
      </geometry>
      <origin xyz="0.0 0.01 0.16799999999999998" rpy="0.0 -0.0 0.0" />
      <material name="drawer_top_main_color">
        <color rgba="0.4 0.4 0.4 1.0" />
      </material>
    </visual>
    <collision name="drawer_back">
      <geometry>
        <box size="0.361 0.02 0.158" />
      </geometry>
      <origin xyz="0.0 0.2865 0.079" rpy="0.0 -0.0 0.0" />
    </collision>
    <collision name="drawer_left">
      <geometry>
        <box size="0.02 0.5529999999999999 0.158" />
      </geometry>
      <origin xyz="-0.17049999999999998 0.0 0.079" rpy="0.0 -0.0 0.0" />
    </collision>
    <collision name="drawer_right">
      <geometry>
        <box size="0.02 0.5529999999999999 0.158" />
      </geometry>
      <origin xyz="0.17049999999999998 0.0 0.079" rpy="0.0 -0.0 0.0" />
    </collision>
    <collision name="drawer_surface_0_0">
      <geometry>
        <box size="0.321 0.5529999999999999 0.02" />
      </geometry>
      <origin xyz="0.0 0.0 0.010000000000000018" rpy="0.0 -0.0 0.0" />
    </collision>
    <collision name="drawer_top">
      <geometry>
        <box size="0.361 0.573 0.02" />
      </geometry>
      <origin xyz="0.0 0.01 0.16799999999999998" rpy="0.0 -0.0 0.0" />
    </collision>
  </link>
  <link name="drawer_drawer_0_0">
    <inertial>
      <origin xyz="0.0 0.0 0.0" rpy="0.0 -0.0 0.0" />
      <mass value="0.1" />
      <inertia ixx="1.0" ixy="0.0" ixz="0.0" iyy="1.0" iyz="0.0" izz="1.0" />
    </inertial>
    <visual><geometry><mesh filename="drawers_extracted/warped_drawer.obj" /></geometry><material name="drawer_drawer_0_0_material"><color rgba="0.8 0.8 0.8 1.0" /></material></visual><collision><geometry><box size="0.357000 0.625800 0.174000" /></geometry><origin xyz="0.000000 0.182800 0.000000" rpy="0 0 0" /></collision></link>
  <link name="world" />
  <link name="drawer" />
  <joint name="drawer_world_fixed_joint" type="fixed">
    <parent link="world" />
    <child link="drawer" />
    <origin xyz="0.0 0.0 0.0" rpy="0.0 -0.0 0.0" />
  </joint>
  <joint name="drawer_corpus_to_drawer_0_0" type="prismatic">
    <parent link="drawer_corpus" />
    <child link="drawer_drawer_0_0" />
    <origin xyz="0.0 -0.27649999999999997 0.08900000000000001" rpy="0.0 -0.0 0.0" />
    <axis xyz="0 -1 0" />
    <limit effort="1000.0" velocity="1.0" lower="0.0" upper="0.46412999999999993" />
  </joint>
  <joint name="drawer_origin_joint" type="fixed">
    <parent link="drawer" />
    <child link="drawer_corpus" />
    <origin xyz="0.0 0.0 0.0" rpy="0.0 -0.0 0.0" />
  </joint>
</robot>